<?xml version="1.0"?>
<sdf version="1.7">
  <model name="four_bar">
    <link name='driving_link'>
      <!-- <pose relative_to='driving_joint'>0 0 0 0 0 0</pose> -->
      <inertial>
        <pose>0 0 0 0 0 0</pose>
        <mass>0.00016893</mass>
        <inertia>
          <ixx>9.7215e-10</ixx>
          <ixy>-4.8913999999999998e-26</ixy>
          <ixz>1.0304e-25</ixz>
          <iyy>9.0105999999999999e-10</iyy>
          <iyz>1.3852e-17</iyz>
          <izz>2.5573999999999999e-10</izz>
        </inertia>
      </inertial>
      <visual name='driving_link_visual'>
        <pose>0 0 -0.01915 0 0 0</pose>
        <geometry>
          <cylinder>
            <radius>0.00075</radius>
            <length>0.0383</length>
          </cylinder>
        </geometry>
        <material>
          <diffuse>1 1 1 1</diffuse>
          <ambient>1 1 1 1</ambient>
        </material>
      </visual>
    </link>

    <joint name='humerus_joint' type='revolute'>
      <pose relative_to='driving_link'>0 0.0 -0.03830 0 1.57 0</pose>
      <parent>driving_link</parent>
      <child>humerus</child>
      <axis>
        <xyz expressed_in="__model__">0 1 0</xyz>
        <limit>
          <lower>-1.79769e+308</lower>
          <upper>1.79769e+308</upper>
        </limit>
        <dynamics>
          <spring_reference>0</spring_reference>
          <spring_stiffness>0.00001</spring_stiffness>
        </dynamics>
      </axis>
    </joint>

    <link name='humerus'>
      <pose relative_to='driving_link'>0 0.0 -0.03830 0 1.57 0</pose>
      <inertial>
        <pose>0.001375 0.00175 0.013055 0 0 0</pose>
        <mass>0.0030354999999999998</mass>
        <inertia>
          <ixx>3.0067e-09</ixx>
          <ixy>-1.1299e-25</ixy>
          <ixz>-2.3232e-24</ixz>
          <iyy>2.9301e-09</iyy>
          <iyz>8.4040999999999998e-16</iyz>
          <izz>3.8589e-10</izz>
        </inertia>
      </inertial>
      <visual name='humerus_visual'>
        <pose>0 0 -0.02 0 0 0</pose>
        <geometry>
          <cylinder>
            <radius>0.00075</radius>
            <length>0.04</length>
          </cylinder>
        </geometry>
        <material>
          <diffuse>1 1 1 1</diffuse>
          <ambient>1 1 1 1</ambient>
        </material>
      </visual>
    </link>


    <link name='radius'>
      <pose relative_to='humerus'>0 0 -0.04 0 -1.57 0 </pose>
      <inertial>
        <pose>0.0015 0.00175 -0.03576 0 0 0</pose>
        <mass>0.00071232000000000001</mass>
        <inertia>
          <ixx>4.3980000000000001e-08</ixx>
          <ixy>-9.9168000000000003e-19</ixy>
          <ixz>4.8890000000000004e-15</ixz>
          <iyy>4.4758000000000003e-08</iyy>
          <iyz>-8.2275000000000001e-16</iyz>
          <izz>1.8231e-09</izz>
        </inertia>
      </inertial>
      <visual name='radius_visual'>
        <pose>0 0 0.05 0 0 0</pose>
        <geometry>
          <cylinder>
            <radius>0.00075</radius>
            <length>0.1</length>
          </cylinder>
        </geometry>
        <material>
          <diffuse>1 1 1 1</diffuse>
          <ambient>1 1 1 1</ambient>
        </material>
      </visual>
    </link>

    <!-- Replaced by bushign -->
    <!-- <joint name='radial_joint' type='revolute'>
      <parent>humerus</parent>
      <child>radius</child>
      <axis>
        <xyz expressed_in="__model__">0 1 0</xyz>
        <limit>
          <lower>-1.79769e+308</lower>
          <upper>1.79769e+308</upper>
        </limit>
        <dynamics>
          <spring_reference>0</spring_reference>
          <spring_stiffness>0.00001</spring_stiffness>
        </dynamics>
      </axis>
    </joint> -->

    <frame name="radial_world_anchor" attached_to="radius">
      <pose relative_to="radius">0 0 0.05 0 0 0</pose>
    </frame>
    <frame name="world_radial_anchor" attached_to="__model__">
      <pose relative_to="__model__">0.005972 0 0.01403177573 -3.141585307179587 -0.93281 -1.5708</pose>
    </frame>
    <joint name='mid_radial_joint' type='revolute'>
      <parent>world_radial_anchor</parent>
      <child>radial_world_anchor</child>
      <axis>
        <xyz>0 1 0</xyz>
        <limit>
          <effort>0</effort>
        </limit>
        <dynamics>
          <damping>0</damping>
          <spring_stiffness>0</spring_stiffness>
        </dynamics>
      </axis>
    </joint>


    <frame name="humerus_radial_bushing" attached_to="humerus">
      <pose relative_to="humerus">0 0 -0.04 0 -1.57079632679 0 </pose>
    </frame>
    <frame name="radial_humerus_bushing" attached_to="radius">
      <pose relative_to="radius">4 0 0 -1.57079632679 0 0</pose>
    </frame>
  </model>
</sdf>